# 에러 처리
## 1. logger사용하기
- `winston`: 우리 회사 로거 모듈
- 로그 단계: error(0), warn(1), info(2), http(3), verbose(4), debug(5), silly(6)
> (1) level 로거에 선언된 로그 단계보다 같거나 낮은 경우에만 로그를 출력
> (2) transports: 로그의 출력 위치
> (3) 로그 양식 지정 가능
> 로그 객체를 생성한 이후에 객체를 호출하는 방식으로 사용할 수 있다.
> 로그의 주요 요구사항: timestamp, 높은 가독성, 로그의 레벨에 따른 반응의 다각화
```javascript
var logger = new winston.Logger({
  level: 'info', // ------ (1)
  transports: [ // ------- (2)
    // 콘솔에 로그 출력
    new winston.transports.Console(),
    // 파일로 로그 저장
    new winston.transports.File({filename:"test.log"})
  ],
  format: combine(timestamp({ format: "YYYY-MM-DD HH:mm:ss" }), json()),// -- (3)
});

// 위에서 선언한 Logger를 원하는 곳에서 사용
logger.info("cashwalk format logger");
// 다음과 같이 출력 됨.
{"level":"info","message":"cashwalk format logger","timestamp":"2022-01-05 16:54:37"}
```
> 앞서 생성한 로그 객체를 활용하여 저장된 로그에 대한 쿼리문을 작성할 수 있다.
```javascript
var options = {
  from: new Date - 24 * 60 * 60 * 1000,
  until: new Date,
  limit: 3,
  start: 0,
  order: 'desc',
  fields: ['message'] // 메세지만 출력
};

logger.query(options, function (err, results) {
  console.log(results);
});
// 출력
{ file: 
   [ { message: 'cashwalk format logger' },
     { message: 'cashwalk format logger' },
     { message: 'cashwalk format logger' } ] }
```
<br>

---

## 2. 테스트 프레임워크
- `Mocha`: 회사 테스트 프레임 워크
> api처리 위주의 테스트에 익숙해져야 한다. 테스트 과정에서 겪는 에러에 익숙해지자.
> 이 과정에서 `mocha`는 효율적인 프레임 워크
> `chai`, `should` 등의 validation 모듈을 추가로 사용하면 가독성을 높일 수 있다.
```javascript
assert.equal(sayHello(), 'hello');// 기존 assert모듈
'hello'.should.equal('hello'); // should 모듈
```
<br>

---

## 3. APM(application performanc management)
- `datadog`: 회사 서드파티 APM 시스템
> 소프트웨어의 적절한 운영과 성능을 관리하고 모니터링
> 개발자의 언어를 운영자의 언어로 변환해주는 과정
<br>

---

## 4. unhandled promise rejection 처리
> 모든 promise체인에 catch를 사용해라, 안그러면 에러는 사라져 버린다.

#### 공식문서
```javascript
function SomeResource() {
  this.loaded = Promise.reject(new Error("Resource not yet loaded!"));
}

const resource = new SomeResource();

process.on("unhandledRejection", (reason, p) => {
  console.log("Unhandled Rejection at: Promise", p, "\nreason:", reason.stack);
  // application specific logging, throwing an error, or other logic here
  console.dir(reason.stack);
});
```
> 그런데 process.on없이 SomeReourse()를 실행했는데도 stack trace는 동일한 내용이 출력되었다. 그러면 사라지는 것은 아니지 않나..?
```javascript
// 실제 회사 코드
process.on('uncaughtException', (error) => {
    logger.error('uncaughtException', (new Date()).toISOString(), error);
    process.exit(1);
});
process.on('unhandledRejection', (reason) => {
    logger.error('unhandledRejection', (new Date()).toISOString(), reason);
    throw reason;
});
```
#### `uncaughtException`의 인자가 error인데 반해 `unhandledRejection`의 인자는 reason인 이유
> `uncaughtException`은 에러로 인한 예외처리
> `unhandledRejection`은 new promise(resolve, reject)의 reject가 처리되지 않은 것을 나타냄 -> 그냥 같은거로 봐도 됨.

<br>

---

## 5. Validation을 위한 모듈
> `joi`, `validator` 등의 모듈이 존재한다.
> 우리 회사의 경우 사용되고 있지는 않지만, 이후 개발에서는 도입을 고려중.
> 유효성 검사를 위한 if문의 가독성을 올려준다.
```javascript
// 회사 쿼리
if (query.signed_value !== check)
// joi사용 쿼리
var memberSchema = Joi.object().keys({
    // 패스워드는 문자열이어야 하고~ 숫자면 1900보다 크고 2013보다 작아야 하며~~ 등등, 인자값을 미리 검사해준다.
    // 이러한 라이브러리를 쓰지 않는 코드는 if(param == number && param > 1900 && ~~) 이런식으로 가독성이 떨어짐.
 password: Joi.string().regex(/^[a-zA-Z0-9]{3,30}$/),
 birthyear: Joi.number().integer().min(1900).max(2013),
 email: Joi.string().email()
});
```

<br>

---

## 6. promise반환
> promise객체를 반환하는 함수의 경우 await를 반드시 붙여주어야 한다.<br>
> 에러가 발생하는 상황에 call stack에 올라간 함수가 달라짐 => stack trace출력 오류가 발생한다.

#### stack trace 정상출력 예
```javascript
async function functionOne() {
  throw new Error("Error here prints the complete stack");
  await new Promise((resolve) => {
    setTimeout(() => {
      resolve();
    }, 1000);
  });
}

async function functionTwo() {
  await functionOne();
}

async function functionThree() {
  await functionTwo();
}

functionThree().catch((error) => {
  console.error(error);
});
```

#### stack trace 비정상 출력 예
```javascript
async function functionOne() {
  await new Promise((resolve) => {
    setTimeout(() => {
      resolve();
    }, 1000);
  });
  throw new Error("Error here prints the incomplete stack");
}

async function functionTwo() {
  await functionOne();
}

async function functionThree() {
  await functionTwo();
}

functionThree().catch((error) => {
  console.error(error);
});
```

#### 정상 출력
Error: Error here prints the complete stack<br>
    <t>at functionOne (/Users/jeongdeoksu/Desktop/main/tmp.js:2:9)<br>
    <t>at functionTwo (/Users/jeongdeoksu/Desktop/main/tmp.js:12:9)<br>
    <t>at functionThree (/Users/jeongdeoksu/Desktop/main/tmp.js:16:9)<br>
   <t>at Object.anonymous (/Users/jeongdeoksu/Desktop/main/tmp.js:19:1)<br>
    <t>at Module._compile (module.js:653:30)<br>
    <t>at Object.Module._extensions..js (module.js:664:10)<br>
    <t>at Module.load (module.js:566:32)<br>
    <t>at tryModuleLoad (module.js:506:12)<br>
    <t>at Function.Module._load (module.js:498:3)<br>
    <t>at Function.Module.runMain (module.js:694:10)<br>
#### 비정상 출력 -> 어디에서 functionOne을 호출했는지 알 수 없다.
Error: Error here prints the incomplete stack<br>
    <t>at functionOne (/Users/jeongdeoksu/Desktop/main/tmp.js:7:9)<br>
    <t>at anonymous

### 정상 출력 이유
> 1) call stack에 functionThree, functionTwo, functionOne순서로 쌓임<br>
> 2) 오류가 발생해서 call stack의 내용이 출력이 되었다.<br>
> 3) functionOne의 setTime callback이 실행된다.(사실상 무시됨)
### 비정장 출력 이유
> 1) call stack에 세 함수가 쌓인다.<br>
> 2) functionOne의 setTime이 call stack에 올라가서 실행되고 1초를 기다리는 중~<br>
> 3) setTime이 `promise`를 반환하고 call stack에 쌓인 함수들이 사라진다.<br>
> 4) setTime이 종료되고 callback함수가 callback queue에 들어간다.<br>
> 5) 이후 Error를 던지는데, callstack에 함수가 없어서 stacktrace가 없다.

### 추가적인 사항
> 최신 버전 node(17.0.0)의 경우, 위의 두 상황에서 모두 stacktrace가 살아서 출력되었음.<br>
> 회사에서 사용하는 node버전(8.15.0)의 경우 stacktrace가 사라지는 현상이 발생.

### 결과적으러
> promise를 반환하는 함수를 사용할 경우, 반드시 앞에 await를 붙여준다. <br>
> promise을 반환한 후 에러가 발생한다면, call stack에 함수가 남아있지 않기 때문에 stack trace가 없다.